Workbook

Sheet 📋 Overview
A1: NUCLEUS SYSTEMS | NS-CMMF v1.0 — Cybersecurity Maturity Measurement Framework
A2: NIST CSF 2.0 · 187+ Controls · 6 Domains · 32 Frameworks & Regulations · 5-Axis Scoring · Hard Scoring Gates · 2026 · Re-engineered & Modernised
B4: Purpose | C4: NS-CMMF v1.0 is a comprehensive, consultable, and regulatory-aligned cybersecurity maturity framework for mid-market and enterprise organizations operating across multiple jurisdictions—modernizing traditional controls to align with cloud-first, AI-driven, and dynamic operating environments. With 187+ fully re-engineered and modernized controls, a 5-axis scoring model, and mapping to 32 frameworks and regulations, it replaces fragmented compliance checklists and opaque maturity ratings with a single, evidence-based approach to measurement and continuous improvement. This Assessment Tool is the operational layer of NS-CMMF v1.0, covering 187 specific controls across 6 NIST CSF 2.0 domains with automated scoring, roadmap prioritisation, and board-ready reporting.
B7: What Makes NS-CMMF Different | C7: 1. SPECIFICITY — Every control addresses one measurable, auditable outcome. Where legacy frameworks have 'endpoint protection' (one checkbox), NS-CMMF has 7 distinct controls: EDR coverage, CIS hardening, Critical patch SLA, Medium patch SLA, EOL management, application allowlisting, and MDM — each with its own evidence standard and regulatory mapping. 2. REGULATORY ALIGNMENT — Every control maps to specific regulatory articles (not general categories): GDPR Art.33-35, NIS2 Art.20-23, DORA Art.5-19, PCI DSS Req.1-12, HIPAA §164.308-312, SOX §404 & §802, CRA Art.13-14, FedRAMP Rev.5, and NIST SP 800-53 Rev.5. 3. MODERNISED CONTROLS — Re-engineered for cloud-first, AI-driven environments. Includes dedicated AI governance, AI threat detection, shadow AI controls, prompt injection prevention, AI model integrity validation, OT/ICS security, CSPM/CIEM, ZTNA, SASE architecture, and container security. 4. FINANCIAL QUANTIFICATION — Cyber risk expressed as EBITDA impact, regulatory fine exposure, and remediation cost — enabling board-level investment decisions rather than instinct-based ones. 5. CONTINUOUS MEASUREMENT — Designed for repeated assessment with longitudinal tracking, evidence lifecycle management, and a living roadmap — not a point-in-time audit instrument.
B10: 5-Axis Scoring Model | C10: Each control is scored across five independent dimensions: • Design Adequacy (20%) — Is the control well-designed, scoped, and mapped to regulatory obligations? • Implementation Coverage (25%) — Is it deployed across 100% of the in-scope population? • Operating Effectiveness (25%) — Does it run consistently with 3-month operational evidence? • Monitoring & Assurance (20%) — Is it independently tested and reported against defined KPIs? • Automation & Resilience (10%) — Is it automated, self-healing, and continuously evidenced? Composite Score = Design×0.20 + Coverage×0.25 + Operating×0.25 + Monitoring×0.20 + Automation×0.10
B13: Hard Scoring Gates | C13: These gates cap maturity regardless of composite score: • No named owner → Maximum L2 (unowned control is not a control) • No operational evidence over 3-month sample → Maximum L3 (documentation ≠ operation) • No KPI or KRI defined → Maximum L4 (unmeasured control cannot be managed) • No automated telemetry → Maximum L5 (continuous evidence requires automation) • Named regulatory obligation demonstrably unmet → Maximum L2 / High Risk • Interview-only evidence (Tier 3) → Maximum L2 / Unverified • Attestation-only evidence (Tier 4) → Maximum L1.5 / Unverified
B16: Evidence Standards | C16: Tier 1 — Automated tool output + independent third-party validation → Full score weight Tier 2 — Documentary evidence + sample testing → Score reduced by 0.3 across all dimensions Tier 3 — Interview only, no corroboration → Capped at L2 / Unverified Tier 4 — Management attestation, no supporting documentation → Capped at L1.5 / Unverified
B19: Maturity Scale | C19: L1 — Initial: Ad hoc, reactive, undocumented. No named owner. Controls exist only after incidents. L2 — Developing: Basic processes exist but inconsistently applied. Some documentation. Manual evidence. L3 — Defined: Standardised, documented, consistently applied. Named owners. Annual review. Systematic evidence. L4 — Managed: Measured, KPI-driven, risk-integrated. Performance tracked. Exceptions formally managed. L5 — Optimised: Automated, adaptive, continuously improving. Self-healing. Independently assured.
B22: Simplification Recommendations | C22: Based on assessment of legacy frameworks and client feedback, NS-CMMF v1.0 incorporates the following simplifications: 1. CONSOLIDATE VENDOR ASSESSMENT — Combined vendor assessment questionnaire, contractual obligations, and sub-processor mapping into a unified TPRM domain view rather than three separate sheets. 2. UNIFIED JML CONTROLS — Joiners/Movers/Leavers consolidated into three specific controls with clear SLA gates, replacing six overlapping IAM procedures. 3. SINGLE PATCH SLA CONTROL — Critical/High and Medium/Low SLAs unified into one Patch Management control with tiered SLA thresholds, eliminating duplicate evidence collection. 4. AI CONTROLS INTEGRATED — AI governance controls distributed across relevant CSF domains (GV for governance, PR for controls, DE for detection, RC for recovery) rather than siloed in a separate AI workstream. 5. EVIDENCE REGISTER SIMPLIFIED — Evidence tracking uses status tiers (Current/Expiring/Expired/Requested) with automated flagging rather than manual evidence management spreadsheets. 6. ROADMAP AUTO-GENERATION — Priority Score (Gap × Domain Weight) automatically populates the roadmap, eliminating manual prioritisation workshops for standard engagements. 7. REGULATORY MAPPING AT CONTROL LEVEL — Framework alignment embedded in each control row rather than maintained as a separate cross-reference matrix, eliminating the need for mapping reconciliation. 8. SINGLE DROPDOWN PER CONTROL — Replaced separate current/target/evidence dropdowns with a single L1-L5 contextual dropdown that preserves control-specific maturity descriptions.
B25: How to Use This Tool | C25: Step 1: SCOPE — Complete the 🔍 Scoping sheet. Answer all Yes/No questions to auto-scope controls for your context. Step 2: ASSESS — Work through each domain sheet. Describe current state in column F, attach evidence in column G, select maturity rating in column H, and set target in column J. Step 3: REVIEW — Open the 📊 Dashboard for your weighted maturity current vs target with priority signals. Step 4: ROADMAP — Use the 🗺️ Roadmap sheet for auto-generated improvement actions ranked by Priority Score. Step 5: REPORT — The 📄 Board Report auto-populates from your scores for executive communication. Step 6: TRACK — Record each completed assessment in 📅 Assessment History for regulatory evidence of improvement.
B28: Version | C28: Nucleus Systems NS-CMMF v1.0 | Cybersecurity Maturity Measurement Framework | 2026 Edition | Re-engineered & Modernised | www.nucleus-systems.com | Centurion, Gauteng, South Africa

Sheet 🔍 Scoping
A1: 🔍 NS-CMMF v1.0 Cybersecurity Maturity Measurement Framework — ASSESSMENT SCOPING QUESTIONNAIRE
A2: Complete this sheet FIRST — answers auto-scope controls. If unsure, answer Yes (conservative scoping).
B4: Q # | C4: Category | D4: Scoping Question | E4: Answer ▼ | F4: Why This Matters | G4: Controls Affected if No
A5: Regulatory
B6: Q1 | C6: Regulatory | D6: Subject to GDPR (EU data protection)? | E6: Yes | F6: Triggers privacy governance, ROPA, DPIA, data subject rights, and breach notification controls. | G6: 8 controls
B7: Q2 | C7: Regulatory | D7: Subject to NIS2 Directive (EU essential or important entity)? | E7: No | F7: Triggers NIS2 management accountability, incident notification, and supply chain security controls. | G7: 3 controls
B8: Q3 | C8: Regulatory | D8: Subject to DORA (EU Digital Operational Resilience Act)? | E8: No | F8: Triggers DORA ICT risk framework, TPSP register, TLPT, and major incident reporting controls. | G8: 4 controls
B9: Q4 | C9: Regulatory | D9: Subject to PCI DSS (processes, stores, or transmits payment card data)? | E9: Yes | F9: Triggers CDE scoping, cardholder data protection, segmentation validation, and logging controls. | G9: 6 controls
B10: Q5 | C10: Regulatory | D10: Subject to HIPAA (US healthcare — PHI protection)? | E10: No | F10: Triggers HIPAA administrative, technical, and physical safeguards; BAA requirements. | G10: 2 controls
B11: Q6 | C11: Regulatory | D11: Subject to SOX (public company — financial reporting controls)? | E11: No | F11: Triggers IT general controls, audit trail requirements, access certification, and financial monitoring. | G11: 2 controls
B12: Q7 | C12: Regulatory | D12: Subject to CCPA or US state privacy laws? | E12: No | F12: Triggers consumer rights fulfilment, deletion capability, and service provider governance. | G12: None
B13: Q8 | C13: Regulatory | D13: Distribute software products in EU subject to Cyber Resilience Act (CRA)? | E13: No | F13: Triggers SBOM, vulnerability disclosure, security-by-design, and ENISA reporting obligations. | G13: 3 controls
B14: Q9 | C14: Regulatory | D14: Hold or seek FedRAMP authorisation for US federal cloud workloads? | E14: No | F14: Triggers FedRAMP baselines, ZTA mandate, 3PAO assessment, and continuous monitoring controls. | G14: 1 controls
A15: Organisation
B16: Q10 | C16: Organisation | D16: 500+ employees or process data of 100,000+ individuals? | E16: Yes | F16: Larger organisations require formal executive accountability and structured audit infrastructure. | G16: None
B17: Q11 | C17: Organisation | D17: Operate across more than 3 countries or jurisdictions? | E17: No | F17: Requires multi-framework regulatory mapping and cross-border data transfer controls. | G17: 2 controls
B18: Q12 | C18: Organisation | D18: Have an existing ISO 27001, SOC 2, or formal GRC programme? | E18: No | F18: Enables integration of NS-CMMF into existing assurance frameworks. | G18: None
A19: Cloud & Infra
B20: Q13 | C20: Cloud & Infra | D20: Operate workloads on AWS, Azure, or GCP? | E20: Yes | F20: Triggers CSPM, CIEM, shared responsibility, ISO 27017, and cloud-native security controls. | G20: 13 controls
B21: Q14 | C21: Cloud & Infra | D21: Operate OT, ICS, SCADA, or industrial control systems? | E21: No | F21: Triggers OT/ICS security, OT-IT network separation, and specialist continuity controls. | G21: 6 controls
B22: Q15 | C22: Cloud & Infra | D22: Use or provide SaaS applications to external customers? | E22: Yes | F22: Triggers SaaS security, API security, multi-tenant isolation, and CASB controls. | G22: None
A23: App Dev
B24: Q16 | C24: App Dev | D24: Develop, build, or maintain software products distributed externally? | E24: Yes | F24: Triggers SBOM, secure SDLC, NIST SSDF, CRA obligations, and supply chain security. | G24: 14 controls
A25: AI & Emerging
B26: Q17 | C26: AI & Emerging | D26: Develop, train, fine-tune, or deploy AI or ML models? | E26: No | F26: Triggers AI governance committee, asset inventory, training data governance, and adversarial testing. | G26: 12 controls
B27: Q18 | C27: AI & Emerging | D27: Use generative AI, LLMs, or automated decision systems affecting individuals? | E27: No | F27: Triggers prompt injection prevention, AI output monitoring, GDPR Art.22, and EU AI Act controls. | G27: 4 controls
B28: Q19 | C28: AI & Emerging | D28: Employees using third-party AI tools (ChatGPT, Copilot, etc.) for work? | E28: Yes | F28: Triggers shadow AI detection, AI AUP enforcement, and DLP-based AI monitoring controls. | G28: 3 controls
A29: Third Parties
B30: Q20 | C30: Third Parties | D30: Rely on third-party ICT providers for critical operations? | E30: Yes | F30: Triggers TPRM programme, DORA TPSP register, vendor assessments, and supply chain controls. | G30: 7 controls
B31: Q21 | C31: Third Parties | D31: Process personal data as a data processor on behalf of other organisations? | E31: No | F31: Triggers processor obligations under GDPR Art.28, contractual requirements, and sub-processor governance. | G31: None
B32: Q22 | C32: Third Parties | D32: Use managed security services (MSSP, SOC-as-a-service)? | E32: No | F32: Triggers MSSP contract review, shared responsibility for detection, and third-party SLA monitoring. | G32: 1 controls
A33: Financial
B34: Q23 | C34: Financial | D34: Hold, process, or manage significant financial assets or critical financial data? | E34: Yes | F34: Triggers SOX financial monitoring, financial system access controls, and change management controls. | G34: None
B37: ⚙️ HOW SCOPING WORKS: Answer Yes/No above. Controls are auto-excluded in domain sheets when you answer No to a relevant question. Override by setting Scope = Apply in any domain sheet. N/A = question not applicable to your organisation (controls remain in scope).

Sheet 📊 Dashboard
A1: NUCLEUS SYSTEMS | NS-CMMF v1.0 — CYBERSECURITY MATURITY MEASUREMENT DASHBOARD
A2: NIST CSF 2.0 · 188 Controls · 6 Domains · 32 Frameworks & Regulations · 5-Axis Maturity Scoring · L1→L5 · Evidence-Based · 2026
B3: Organisation: | C3: Acacia Financial Services Ltd | F3: Assessment Date: | G3: 04 September 2026 | I3: Assessor: | J3: [Your Name] — Lead Assessor, NS-CMMF v1.0
B4: 📊 DOMAIN MATURITY — CURRENT STATE vs TARGET (Weighted by domain criticality)
C5: Domain | D5: Weight | E5: Current Avg (/5.0) | F5: Maturity % | G5: Level | H5: Target Avg (/5.0) | I5: Target % | J5: Target Level | K5: Gap | L5: Priority Signal | M5: Controls Rated % | N5: Quick Wins Available
B6: 🏛️ | C6: GOVERN — Leadership, Strategy & Risk Governance | D6: 0.16 | E6: =IFERROR('GV Govern'!J2,"") -> 1.1481481 | F6: =IFERROR(IF(E6="","",E6/5),"") -> 0.22962963 | G6: =IFERROR(IF(E6=0,"⬜ Not Assessed",IF(E6<1.5,"🔴 L1 — Initial",IF(E6<2.5,"🟠 L2 — Developing",IF(E6<3.5,"🟡 L3 — Defined",IF(E6<4.5,"🟢 L4 — Managed","💎 L5 — Optimised"))))),"") -> 🔴 L1 — Initial | H6: =IFERROR('GV Govern'!L2,"") -> 3.3703704 | I6: =IFERROR(IF(H6="","",H6/5),"") -> 0.67407407 | J6: =IFERROR(IF(H6=0,"Not Set",IF(H6<1.5,"L1 — Initial",IF(H6<2.5,"L2 — Developing",IF(H6<3.5,"L3 — Defined",IF(H6<4.5,"L4 — Managed","L5 — Optimised"))))),"") -> L3 — Defined | K6: =IFERROR(IF(OR(E6="",H6=""),"—",H6-E6),"—") -> 2.2222222 | L6: =IFERROR(IF(OR(E6="",H6=""),"—",IF(H6-E6>=3,"🔴 Critical — Immediate Action",IF(H6-E6>=2,"🟠 High — Action This Quarter",IF(H6-E6>=1,"🟡 Medium — Plan Within 6 Months",IF(H6-E6>0,"🔵 Low — Schedule & Monitor",IF(H6-E6=0,"✅ Target Met","⬆️ Exceeds Target")))))),"") -> 🟠 High — Action This Quarter | M6: =IFERROR('GV Govern'!N2,"—") -> 27 / 27 applicable | N6: =COUNTIFS('🗺️ Roadmap'!A5:A32,">0",'🗺️ Roadmap'!A5:A32,"<="&16%*1.5) -> 9
B7: 🔍 | C7: IDENTIFY — Assets, Data, Risk & Exposure | D7: 0.1 | E7: =IFERROR('ID Identify'!J2,"") -> 1.3157895 | F7: =IFERROR(IF(E7="","",E7/5),"") -> 0.26315789 | G7: =IFERROR(IF(E7=0,"⬜ Not Assessed",IF(E7<1.5,"🔴 L1 — Initial",IF(E7<2.5,"🟠 L2 — Developing",IF(E7<3.5,"🟡 L3 — Defined",IF(E7<4.5,"🟢 L4 — Managed","💎 L5 — Optimised"))))),"") -> 🔴 L1 — Initial | H7: =IFERROR('ID Identify'!L2,"") -> 3.4736842 | I7: =IFERROR(IF(H7="","",H7/5),"") -> 0.69473684 | J7: =IFERROR(IF(H7=0,"Not Set",IF(H7<1.5,"L1 — Initial",IF(H7<2.5,"L2 — Developing",IF(H7<3.5,"L3 — Defined",IF(H7<4.5,"L4 — Managed","L5 — Optimised"))))),"") -> L3 — Defined | K7: =IFERROR(IF(OR(E7="",H7=""),"—",H7-E7),"—") -> 2.1578947 | L7: =IFERROR(IF(OR(E7="",H7=""),"—",IF(H7-E7>=3,"🔴 Critical — Immediate Action",IF(H7-E7>=2,"🟠 High — Action This Quarter",IF(H7-E7>=1,"🟡 Medium — Plan Within 6 Months",IF(H7-E7>0,"🔵 Low — Schedule & Monitor",IF(H7-E7=0,"✅ Target Met","⬆️ Exceeds Target")))))),"") -> 🟠 High — Action This Quarter | M7: =IFERROR('ID Identify'!N2,"—") -> 19 / 19 applicable | N7: =COUNTIFS('🗺️ Roadmap'!A33:A54,">0",'🗺️ Roadmap'!A33:A54,"<="&10%*1.5) -> 7
B8: 🛡️ | C8: PROTECT — Controls, Architecture & Safeguards | D8: 0.26 | E8: =IFERROR('PR Protect'!J2,"") -> 1.36 | F8: =IFERROR(IF(E8="","",E8/5),"") -> 0.272 | G8: =IFERROR(IF(E8=0,"⬜ Not Assessed",IF(E8<1.5,"🔴 L1 — Initial",IF(E8<2.5,"🟠 L2 — Developing",IF(E8<3.5,"🟡 L3 — Defined",IF(E8<4.5,"🟢 L4 — Managed","💎 L5 — Optimised"))))),"") -> 🔴 L1 — Initial | H8: =IFERROR('PR Protect'!L2,"") -> 3.4666667 | I8: =IFERROR(IF(H8="","",H8/5),"") -> 0.69333333 | J8: =IFERROR(IF(H8=0,"Not Set",IF(H8<1.5,"L1 — Initial",IF(H8<2.5,"L2 — Developing",IF(H8<3.5,"L3 — Defined",IF(H8<4.5,"L4 — Managed","L5 — Optimised"))))),"") -> L3 — Defined | K8: =IFERROR(IF(OR(E8="",H8=""),"—",H8-E8),"—") -> 2.1066667 | L8: =IFERROR(IF(OR(E8="",H8=""),"—",IF(H8-E8>=3,"🔴 Critical — Immediate Action",IF(H8-E8>=2,"🟠 High — Action This Quarter",IF(H8-E8>=1,"🟡 Medium — Plan Within 6 Months",IF(H8-E8>0,"🔵 Low — Schedule & Monitor",IF(H8-E8=0,"✅ Target Met","⬆️ Exceeds Target")))))),"") -> 🟠 High — Action This Quarter | M8: =IFERROR('PR Protect'!N2,"—") -> 78 / 78 applicable | N8: =COUNTIFS('🗺️ Roadmap'!A55:A137,">0",'🗺️ Roadmap'!A55:A137,"<="&26%*1.5) -> 21
B9: 📡 | C9: DETECT — Monitoring, Detection & Threat Intelligence | D9: 0.14 | E9: =IFERROR('DE Detect'!J2,"") -> 1.1111111 | F9: =IFERROR(IF(E9="","",E9/5),"") -> 0.22222222 | G9: =IFERROR(IF(E9=0,"⬜ Not Assessed",IF(E9<1.5,"🔴 L1 — Initial",IF(E9<2.5,"🟠 L2 — Developing",IF(E9<3.5,"🟡 L3 — Defined",IF(E9<4.5,"🟢 L4 — Managed","💎 L5 — Optimised"))))),"") -> 🔴 L1 — Initial | H9: =IFERROR('DE Detect'!L2,"") -> 3.3888889 | I9: =IFERROR(IF(H9="","",H9/5),"") -> 0.67777778 | J9: =IFERROR(IF(H9=0,"Not Set",IF(H9<1.5,"L1 — Initial",IF(H9<2.5,"L2 — Developing",IF(H9<3.5,"L3 — Defined",IF(H9<4.5,"L4 — Managed","L5 — Optimised"))))),"") -> L3 — Defined | K9: =IFERROR(IF(OR(E9="",H9=""),"—",H9-E9),"—") -> 2.2777778 | L9: =IFERROR(IF(OR(E9="",H9=""),"—",IF(H9-E9>=3,"🔴 Critical — Immediate Action",IF(H9-E9>=2,"🟠 High — Action This Quarter",IF(H9-E9>=1,"🟡 Medium — Plan Within 6 Months",IF(H9-E9>0,"🔵 Low — Schedule & Monitor",IF(H9-E9=0,"✅ Target Met","⬆️ Exceeds Target")))))),"") -> 🟠 High — Action This Quarter | M9: =IFERROR('DE Detect'!N2,"—") -> 18 / 18 applicable | N9: =COUNTIFS('🗺️ Roadmap'!A138:A159,">0",'🗺️ Roadmap'!A138:A159,"<="&14%*1.5) -> 3
B10: 🚨 | C10: RESPOND — Incident Management & Regulatory Notification | D10: 0.11 | E10: =IFERROR('RS Respond'!J2,"") -> 1.2857143 | F10: =IFERROR(IF(E10="","",E10/5),"") -> 0.25714286 | G10: =IFERROR(IF(E10=0,"⬜ Not Assessed",IF(E10<1.5,"🔴 L1 — Initial",IF(E10<2.5,"🟠 L2 — Developing",IF(E10<3.5,"🟡 L3 — Defined",IF(E10<4.5,"🟢 L4 — Managed","💎 L5 — Optimised"))))),"") -> 🔴 L1 — Initial | H10: =IFERROR('RS Respond'!L2,"") -> 3.4285714 | I10: =IFERROR(IF(H10="","",H10/5),"") -> 0.68571429 | J10: =IFERROR(IF(H10=0,"Not Set",IF(H10<1.5,"L1 — Initial",IF(H10<2.5,"L2 — Developing",IF(H10<3.5,"L3 — Defined",IF(H10<4.5,"L4 — Managed","L5 — Optimised"))))),"") -> L3 — Defined | K10: =IFERROR(IF(OR(E10="",H10=""),"—",H10-E10),"—") -> 2.1428571 | L10: =IFERROR(IF(OR(E10="",H10=""),"—",IF(H10-E10>=3,"🔴 Critical — Immediate Action",IF(H10-E10>=2,"🟠 High — Action This Quarter",IF(H10-E10>=1,"🟡 Medium — Plan Within 6 Months",IF(H10-E10>0,"🔵 Low — Schedule & Monitor",IF(H10-E10=0,"✅ Target Met","⬆️ Exceeds Target")))))),"") -> 🟠 High — Action This Quarter | M10: =IFERROR('RS Respond'!N2,"—") -> 14 / 14 applicable | N10: =COUNTIFS('🗺️ Roadmap'!A160:A175,">0",'🗺️ Roadmap'!A160:A175,"<="&11%*1.5) -> 6
B11: ♻️ | C11: RECOVER — Resilience, Continuity & Validation | D11: 0.1 | E11: =IFERROR('RC Recover'!J2,"") -> 1.0714286 | F11: =IFERROR(IF(E11="","",E11/5),"") -> 0.21428571 | G11: =IFERROR(IF(E11=0,"⬜ Not Assessed",IF(E11<1.5,"🔴 L1 — Initial",IF(E11<2.5,"🟠 L2 — Developing",IF(E11<3.5,"🟡 L3 — Defined",IF(E11<4.5,"🟢 L4 — Managed","💎 L5 — Optimised"))))),"") -> 🔴 L1 — Initial | H11: =IFERROR('RC Recover'!L2,"") -> 3.2142857 | I11: =IFERROR(IF(H11="","",H11/5),"") -> 0.64285714 | J11: =IFERROR(IF(H11=0,"Not Set",IF(H11<1.5,"L1 — Initial",IF(H11<2.5,"L2 — Developing",IF(H11<3.5,"L3 — Defined",IF(H11<4.5,"L4 — Managed","L5 — Optimised"))))),"") -> L3 — Defined | K11: =IFERROR(IF(OR(E11="",H11=""),"—",H11-E11),"—") -> 2.1428571 | L11: =IFERROR(IF(OR(E11="",H11=""),"—",IF(H11-E11>=3,"🔴 Critical — Immediate Action",IF(H11-E11>=2,"🟠 High — Action This Quarter",IF(H11-E11>=1,"🟡 Medium — Plan Within 6 Months",IF(H11-E11>0,"🔵 Low — Schedule & Monitor",IF(H11-E11=0,"✅ Target Met","⬆️ Exceeds Target")))))),"") -> 🟠 High — Action This Quarter | M11: =IFERROR('RC Recover'!N2,"—") -> 14 / 14 applicable | N11: =COUNTIFS('🗺️ Roadmap'!A176:A192,">0",'🗺️ Roadmap'!A176:A192,"<="&10%*1.5) -> 3
B12: 📊 WEIGHTED OVERALL MATURITY | E12: =IFERROR((E6*D6+E7*D7+E8*D8+E9*D9+E10*D10+E11*D11)/(D6+D7+D8+D9+D10+D11),"") -> 1.2333444 | F12: =IFERROR(IF(E12=0,"",E12/5),"") -> 0.24666888 | G12: =IFERROR(IF(E12=0,"⬜ Not Assessed",IF(E12<1.5,"🔴 L1",IF(E12<2.5,"🟠 L2",IF(E12<3.5,"🟡 L3",IF(E12<4.5,"🟢 L4","💎 L5"))))),"") -> 🔴 L1 | H12: =IFERROR((H6*D6+H7*D7+H8*D8+H9*D9+H10*D10+H11*D11)/(D6+D7+D8+D9+D10+D11),"") -> 3.4034217 | I12: =IFERROR(IF(H12=0,"",H12/5),"") -> 0.68068434 | J12: =IFERROR(IF(H12=0,"Not Set",IF(H12<1.5,"L1",IF(H12<2.5,"L2",IF(H12<3.5,"L3",IF(H12<4.5,"L4","L5"))))),"") -> L3 | K12: =IFERROR(IF(OR(E12="",H12=""),"—",H12-E12),"—") -> 2.1700773 | L12: Weighted maturity across all in-scope assessed controls · Regulatory compliance floors applied
B14: 📌 REGULATORY COMPLIANCE FLOORS — Controls capped due to unmet regulatory obligations
B15: ⚠ NIS2 incident notification capability absent or untested → minimum High Risk (NIS2 essential/important entities)
B16: ⚠ DORA major incident reporting process not established (EU financial entities) → minimum High Risk
B17: ⚠ GDPR ROPA absent or >50% incomplete → minimum High Risk (direct GDPR Art.30 violation)
B18: ⚠ PCI CDE scope unconfirmed or segmentation untested → minimum Critical Risk (PCI DSS non-compliance)
B19: ⚠ HIPAA risk analysis not conducted or >12 months outdated → minimum High Risk
B20: ⚠ FedRAMP ATO expired or not obtained for federal cloud workloads → minimum Critical Risk
B21: ⚠ CRA vulnerability disclosure policy absent for EU-distributed software → minimum High Risk (CRA Art.13)
B22: ⚠ SOX IT general controls not evidenced for in-scope financial systems → minimum High Risk (SOX §404)
B24: 💰 REMEDIATION & IMPROVEMENT COST SUMMARY — From Roadmap Tab (Enter costs in Roadmap → auto-populate here)
B25: Domain | C25: Controls | D25: Weight | E25: Internal Cost (Staff Time) | F25: External Once-Off | G25: External Recurring /yr | H25: Software / Tool Cost | I25: Total Once-Off | J25: Total Annual | K25: Effort Signal | L25: Notes
B26: 🏛️ GOVERN | C26: 28 | D26: 16% | E26: =SUMIF('🗺️ Roadmap'!$B$5:$B$192,"*GV Govern*",'🗺️ Roadmap'!$J$5:$J$192) -> 80250 | F26: =SUMIF('🗺️ Roadmap'!$B$5:$B$192,"*GV Govern*",'🗺️ Roadmap'!$K$5:$K$192) -> 45000 | G26: =SUMIF('🗺️ Roadmap'!$B$5:$B$192,"*GV Govern*",'🗺️ Roadmap'!$L$5:$L$192) -> 0 | H26: =SUMIF('🗺️ Roadmap'!$B$5:$B$192,"*GV Govern*",'🗺️ Roadmap'!$M$5:$M$192) -> 0 | I26: =SUMIF('🗺️ Roadmap'!$B$5:$B$192,"*GV Govern*",'🗺️ Roadmap'!$N$5:$N$192) -> 125250 | J26: =SUMIF('🗺️ Roadmap'!$B$5:$B$192,"*GV Govern*",'🗺️ Roadmap'!$O$5:$O$192) -> 0 | K26: =IF(I26=0,"⬜ Not Estimated",IF(I26<50000,"🟢 Low (< 50K)",IF(I26<200000,"🟡 Medium (50K–200K)",IF(I26<500000,"🟠 High (200K–500K)","🔴 Major (500K+)")))) -> 🟡 Medium (50K–200K)
B27: 🔍 IDENTIFY | C27: 22 | D27: 10% | E27: =SUMIF('🗺️ Roadmap'!$B$5:$B$192,"*ID Identify*",'🗺️ Roadmap'!$J$5:$J$192) -> 59250 | F27: =SUMIF('🗺️ Roadmap'!$B$5:$B$192,"*ID Identify*",'🗺️ Roadmap'!$K$5:$K$192) -> 95000 | G27: =SUMIF('🗺️ Roadmap'!$B$5:$B$192,"*ID Identify*",'🗺️ Roadmap'!$L$5:$L$192) -> 0 | H27: =SUMIF('🗺️ Roadmap'!$B$5:$B$192,"*ID Identify*",'🗺️ Roadmap'!$M$5:$M$192) -> 18000 | I27: =SUMIF('🗺️ Roadmap'!$B$5:$B$192,"*ID Identify*",'🗺️ Roadmap'!$N$5:$N$192) -> 172250 | J27: =SUMIF('🗺️ Roadmap'!$B$5:$B$192,"*ID Identify*",'🗺️ Roadmap'!$O$5:$O$192) -> 0 | K27: =IF(I27=0,"⬜ Not Estimated",IF(I27<50000,"🟢 Low (< 50K)",IF(I27<200000,"🟡 Medium (50K–200K)",IF(I27<500000,"🟠 High (200K–500K)","🔴 Major (500K+)")))) -> 🟡 Medium (50K–200K)
B28: 🛡️ PROTECT | C28: 83 | D28: 26% | E28: =SUMIF('🗺️ Roadmap'!$B$5:$B$192,"*PR Protect*",'🗺️ Roadmap'!$J$5:$J$192) -> 226750 | F28: =SUMIF('🗺️ Roadmap'!$B$5:$B$192,"*PR Protect*",'🗺️ Roadmap'!$K$5:$K$192) -> 55000 | G28: =SUMIF('🗺️ Roadmap'!$B$5:$B$192,"*PR Protect*",'🗺️ Roadmap'!$L$5:$L$192) -> 0 | H28: =SUMIF('🗺️ Roadmap'!$B$5:$B$192,"*PR Protect*",'🗺️ Roadmap'!$M$5:$M$192) -> 112000 | I28: =SUMIF('🗺️ Roadmap'!$B$5:$B$192,"*PR Protect*",'🗺️ Roadmap'!$N$5:$N$192) -> 393750 | J28: =SUMIF('🗺️ Roadmap'!$B$5:$B$192,"*PR Protect*",'🗺️ Roadmap'!$O$5:$O$192) -> 0 | K28: =IF(I28=0,"⬜ Not Estimated",IF(I28<50000,"🟢 Low (< 50K)",IF(I28<200000,"🟡 Medium (50K–200K)",IF(I28<500000,"🟠 High (200K–500K)","🔴 Major (500K+)")))) -> 🟠 High (200K–500K)
B29: 📡 DETECT | C29: 22 | D29: 14% | E29: =SUMIF('🗺️ Roadmap'!$B$5:$B$192,"*DE Detect*",'🗺️ Roadmap'!$J$5:$J$192) -> 64250 | F29: =SUMIF('🗺️ Roadmap'!$B$5:$B$192,"*DE Detect*",'🗺️ Roadmap'!$K$5:$K$192) -> 0 | G29: =SUMIF('🗺️ Roadmap'!$B$5:$B$192,"*DE Detect*",'🗺️ Roadmap'!$L$5:$L$192) -> 36000 | H29: =SUMIF('🗺️ Roadmap'!$B$5:$B$192,"*DE Detect*",'🗺️ Roadmap'!$M$5:$M$192) -> 138000 | I29: =SUMIF('🗺️ Roadmap'!$B$5:$B$192,"*DE Detect*",'🗺️ Roadmap'!$N$5:$N$192) -> 202250 | J29: =SUMIF('🗺️ Roadmap'!$B$5:$B$192,"*DE Detect*",'🗺️ Roadmap'!$O$5:$O$192) -> 36000 | K29: =IF(I29=0,"⬜ Not Estimated",IF(I29<50000,"🟢 Low (< 50K)",IF(I29<200000,"🟡 Medium (50K–200K)",IF(I29<500000,"🟠 High (200K–500K)","🔴 Major (500K+)")))) -> 🟠 High (200K–500K)
B30: 🚨 RESPOND | C30: 16 | D30: 11% | E30: =SUMIF('🗺️ Roadmap'!$B$5:$B$192,"*RS Respond*",'🗺️ Roadmap'!$J$5:$J$192) -> 35000 | F30: =SUMIF('🗺️ Roadmap'!$B$5:$B$192,"*RS Respond*",'🗺️ Roadmap'!$K$5:$K$192) -> 0 | G30: =SUMIF('🗺️ Roadmap'!$B$5:$B$192,"*RS Respond*",'🗺️ Roadmap'!$L$5:$L$192) -> 0 | H30: =SUMIF('🗺️ Roadmap'!$B$5:$B$192,"*RS Respond*",'🗺️ Roadmap'!$M$5:$M$192) -> 0 | I30: =SUMIF('🗺️ Roadmap'!$B$5:$B$192,"*RS Respond*",'🗺️ Roadmap'!$N$5:$N$192) -> 35000 | J30: =SUMIF('🗺️ Roadmap'!$B$5:$B$192,"*RS Respond*",'🗺️ Roadmap'!$O$5:$O$192) -> 0 | K30: =IF(I30=0,"⬜ Not Estimated",IF(I30<50000,"🟢 Low (< 50K)",IF(I30<200000,"🟡 Medium (50K–200K)",IF(I30<500000,"🟠 High (200K–500K)","🔴 Major (500K+)")))) -> 🟢 Low (< 50K)
B31: ♻️ RECOVER | C31: 17 | D31: 10% | E31: =SUMIF('🗺️ Roadmap'!$B$5:$B$192,"*RC Recover*",'🗺️ Roadmap'!$J$5:$J$192) -> 49250 | F31: =SUMIF('🗺️ Roadmap'!$B$5:$B$192,"*RC Recover*",'🗺️ Roadmap'!$K$5:$K$192) -> 28000 | G31: =SUMIF('🗺️ Roadmap'!$B$5:$B$192,"*RC Recover*",'🗺️ Roadmap'!$L$5:$L$192) -> 0 | H31: =SUMIF('🗺️ Roadmap'!$B$5:$B$192,"*RC Recover*",'🗺️ Roadmap'!$M$5:$M$192) -> 0 | I31: =SUMIF('🗺️ Roadmap'!$B$5:$B$192,"*RC Recover*",'🗺️ Roadmap'!$N$5:$N$192) -> 77250 | J31: =SUMIF('🗺️ Roadmap'!$B$5:$B$192,"*RC Recover*",'🗺️ Roadmap'!$O$5:$O$192) -> 0 | K31: =IF(I31=0,"⬜ Not Estimated",IF(I31<50000,"🟢 Low (< 50K)",IF(I31<200000,"🟡 Medium (50K–200K)",IF(I31<500000,"🟠 High (200K–500K)","🔴 Major (500K+)")))) -> 🟡 Medium (50K–200K)
B32: TOTAL — ALL 188 CONTROLS | C32: 188 | D32: 100% | E32: =SUM(E26:E31) -> 514750 | F32: =SUM(F26:F31) -> 223000 | G32: =SUM(G26:G31) -> 36000 | H32: =SUM(H26:H31) -> 268000 | I32: =SUM(I26:I31) -> 1005750 | J32: =SUM(J26:J31) -> 36000 | K32: =IF(I32=0,"⬜ Not Estimated",IF(I32<50000,"🟢 Low (< 50K)",IF(I32<200000,"🟡 Medium (50K–200K)",IF(I32<500000,"🟠 High (200K–500K)","🔴 Major (500K+)")))) -> 🔴 Major (500K+)
B34: 📋 HOW TO USE: Enter cost estimates per control in the Roadmap tab (columns J–M: Internal / External Once-Off / External Recurring / Software). Domain totals and the grand total auto-populate above. Once-Off cost = CAPEX + year-1 implementation. Annual cost = ongoing OPEX + licensing.

Sheet 📄 Board Report
B2: NUCLEUS SYSTEMS | CONFIDENTIAL
B3: CYBERSECURITY MATURITY BOARD REPORT
B4: NS-CMMF v1.0 · 188 Controls · 6 Domains · 32 Frameworks · 5-Axis Scoring · 2026
C6: Organisation: | D6: ='📊 Dashboard'!C3 -> Acacia Financial Services Ltd | F6: Date: | G6: ='📊 Dashboard'!G3 -> 04 September 2026
C8: 📊 MATURITY SUMMARY — Current vs Target by Domain
C9: Domain | D9: Weight | E9: Current Score | F9: Level | G9: Target | H9: Priority
C10: 🏛️ GOVERN — Leadership, Strategy & Risk Governance | D10: ='📊 Dashboard'!D6 -> 0.16 | E10: ='📊 Dashboard'!E6 -> 1.1481481 | F10: ='📊 Dashboard'!G6 -> 🔴 L1 — Initial | G10: ='📊 Dashboard'!H6 -> 3.3703704 | H10: ='📊 Dashboard'!L6 -> 🟠 High — Action This Quarter
C11: 🔍 IDENTIFY — Assets, Data, Risk & Exposure | D11: ='📊 Dashboard'!D7 -> 0.1 | E11: ='📊 Dashboard'!E7 -> 1.3157895 | F11: ='📊 Dashboard'!G7 -> 🔴 L1 — Initial | G11: ='📊 Dashboard'!H7 -> 3.4736842 | H11: ='📊 Dashboard'!L7 -> 🟠 High — Action This Quarter
C12: 🛡️ PROTECT — Controls, Architecture & Safeguards | D12: ='📊 Dashboard'!D8 -> 0.26 | E12: ='📊 Dashboard'!E8 -> 1.36 | F12: ='📊 Dashboard'!G8 -> 🔴 L1 — Initial | G12: ='📊 Dashboard'!H8 -> 3.4666667 | H12: ='📊 Dashboard'!L8 -> 🟠 High — Action This Quarter
C13: 📡 DETECT — Monitoring, Detection & Threat Intelligence | D13: ='📊 Dashboard'!D9 -> 0.14 | E13: ='📊 Dashboard'!E9 -> 1.1111111 | F13: ='📊 Dashboard'!G9 -> 🔴 L1 — Initial | G13: ='📊 Dashboard'!H9 -> 3.3888889 | H13: ='📊 Dashboard'!L9 -> 🟠 High — Action This Quarter
C14: 🚨 RESPOND — Incident Management & Regulatory Notification | D14: ='📊 Dashboard'!D10 -> 0.11 | E14: ='📊 Dashboard'!E10 -> 1.2857143 | F14: ='📊 Dashboard'!G10 -> 🔴 L1 — Initial | G14: ='📊 Dashboard'!H10 -> 3.4285714 | H14: ='📊 Dashboard'!L10 -> 🟠 High — Action This Quarter
C15: ♻️ RECOVER — Resilience, Continuity & Validation | D15: ='📊 Dashboard'!D11 -> 0.1 | E15: ='📊 Dashboard'!E11 -> 1.0714286 | F15: ='📊 Dashboard'!G11 -> 🔴 L1 — Initial | G15: ='📊 Dashboard'!H11 -> 3.2142857 | H15: ='📊 Dashboard'!L11 -> 🟠 High — Action This Quarter
C16: WEIGHTED OVERALL | E16: ='📊 Dashboard'!E12 -> 1.2333444 | F16: ='📊 Dashboard'!G12 -> 🔴 L1 | G16: ='📊 Dashboard'!H12 -> 3.4034217 | H16: ='📊 Dashboard'!J12 -> L3
C18: 📌 BOARD GOVERNANCE NOTES
C19: Domains scoring below L3.0 require executive attention with named remediation owners and defined timelines.
C20: Any domain with Gap ≥ 3.0 levels should be escalated to the Board Risk Committee with a costed remediation plan within 30 days.
C21: Regulatory compliance floors override design maturity — unmet obligations cannot be remediated by documentation alone.
C22: An overall weighted score below 3.0 indicates the organisation has not achieved enterprise baseline and may face insurability challenges.
C23: Security investment must be board-approved annually with quarterly progress reporting against the 5-axis model.
C25: 💰 REMEDIATION COST SUMMARY
C26: Enter cost estimates in the Roadmap tab to auto-populate. All figures in base currency.
C27: Domain | D27: Controls | E27: Once-Off Cost | F27: Annual Cost | G27: Priority | H27: Est. ROI
C28: 🏛️ GOVERN | D28: 28 | E28: ='🗺️ Roadmap'!L194 -> 125250 | F28: ='🗺️ Roadmap'!M194 -> 0 | G28: ='📊 Dashboard'!L6 -> 🟠 High — Action This Quarter | H28: Quantify in Roadmap
C29: 🔍 IDENTIFY | D29: 22 | E29: ='🗺️ Roadmap'!L195 -> 172250 | F29: ='🗺️ Roadmap'!M195 -> 0 | G29: ='📊 Dashboard'!L7 -> 🟠 High — Action This Quarter | H29: Quantify in Roadmap
C30: 🛡️ PROTECT | D30: 83 | E30: ='🗺️ Roadmap'!L196 -> 393750 | F30: ='🗺️ Roadmap'!M196 -> 0 | G30: ='📊 Dashboard'!L8 -> 🟠 High — Action This Quarter | H30: Quantify in Roadmap
C31: 📡 DETECT | D31: 22 | E31: ='🗺️ Roadmap'!L197 -> 202250 | F31: ='🗺️ Roadmap'!M197 -> 36000 | G31: ='📊 Dashboard'!L9 -> 🟠 High — Action This Quarter | H31: Quantify in Roadmap
C32: 🚨 RESPOND | D32: 16 | E32: ='🗺️ Roadmap'!L198 -> 35000 | F32: ='🗺️ Roadmap'!M198 -> 0 | G32: ='📊 Dashboard'!L10 -> 🟠 High — Action This Quarter | H32: Quantify in Roadmap
C33: ♻️ RECOVER | D33: 17 | E33: ='🗺️ Roadmap'!L199 -> 77250 | F33: ='🗺️ Roadmap'!M199 -> 0 | G33: ='📊 Dashboard'!L11 -> 🟠 High — Action This Quarter | H33: Quantify in Roadmap
C34: TOTAL — ALL 188 CONTROLS | E34: ='🗺️ Roadmap'!L201 -> 1005750 | F34: ='🗺️ Roadmap'!M201 -> 36000
C36: 📌 COST GOVERNANCE: The total once-off investment represents the estimated cost to achieve target maturity across all assessed domains. Annual recurring costs represent sustained operational investment required to maintain the target security posture. Boards should approve these costs against regulatory fine exposure and cyber debt risk quantified in the Domain Assessment report.

Sheet 🗺️ Roadmap
A1: NUCLEUS SYSTEMS | NS-CMMF v1.0 — SECURITY IMPROVEMENT ROADMAP — 188 CONTROLS | Cost Model & Prioritisation
A2: Auto-populated from domain ratings · Priority Score = Gap × Domain Weight · Col D = auto-generated recommendation (rate controls in domain tabs first) · Enter costs in J–M · Assign owners in G and target quarters in F
A3: Assessment & Planning | I3: Notes | J3: Cost Inputs — Enter Estimates | N3: Auto-Totals | P3: Assumptions
A4: Priority Score | B4: Domain | C4: Control Name | D4: Recommended Action | E4: Effort Estimate | F4: Target Quarter | G4: Owner | H4: Status | I4: Notes | J4: Internal Cost (Staff Time) | K4: External Once-Off | L4: External Recurring /yr | M4: Software / Tool Cost | N4: Total Once-Off | O4: Total Annual | P4: Cost Assumptions
A5: 0.16 | B5: 🏛️ GV Govern | C5: CISO / Security Leadership | D5: =IFERROR(IF('GV Govern'!P4="⏳ Complete rating and target to generate recommendation.","⏳ Rate this control in the domain sheet to auto-generate.",'GV Govern'!P4),"—") -> Standardise CISO / Security Leadership: formalise all documentation, apply the control consistently across all in-scope assets, close remaining coverage gaps, and ensure evidence is collected routinely. Exceptions must be formally managed with named owners and defined expiry dates. | E5: High (1-3 months) | F5: Q2 2027 | G5: Jean-Paul Nkeng — Managing Director | H5: Not Started | J5: 3000 | K5: 0 | L5: 0 | M5: 0 | N5: =IFERROR(SUM(J5,K5,M5),0) -> 3000 | O5: =IFERROR(SUM(L5),0) -> 0 | P5: Illustrative estimate (USD). Internal cost = staff days x 250/day blended rate. External and tool costs are indicative list pricing, not quotations.
A6: 0.32 | B6: 🏛️ GV Govern | C6: Cybersecurity Strategy & Programme | D6: =IFERROR(IF('GV Govern'!P5="⏳ Complete rating and target to generate recommendation.","⏳ Rate this control in the domain sheet to auto-generate.",'GV Govern'!P5),"—") -> Standardise Cybersecurity Strategy & Programme: formalise all documentation, apply the control consistently across all in-scope assets, close remaining coverage gaps, and ensure evidence is collected routinely. Exceptions must be formally managed with named owners and defined expiry dates. | E6: High (1-3 months) | F6: Q2 2027 | G6: Jean-Paul Nkeng — Managing Director | H6: Not Started | J6: 3000 | N6: =IFERROR(SUM(J6,K6,M6),0) -> 3000 | O6: =IFERROR(SUM(L6),0) -> 0 | P6: Illustrative estimate (USD). Internal cost = staff days x 250/day blended rate. External and tool costs are indicative list pricing, not quotations.
A7: 0.32 | B7: 🏛️ GV Govern | C7: Cyber Budget & Investment Model | D7: =IFERROR(IF('GV Govern'!P6="⏳ Complete rating and target to generate recommendation.","⏳ Rate this control in the domain sheet to auto-generate.",'GV Govern'!P6),"—") -> Standardise Cyber Budget & Investment Model: formalise all documentation, apply the control consistently across all in-scope assets, close remaining coverage gaps, and ensure evidence is collected routinely. Exceptions must be formally managed with named owners and defined expiry dates. | E7: Medium (1-4 weeks) | F7: Q3 2027 | G7: Paul Mbarga — Finance Director | H7: Not Started | J7: 1250 | N7: =IFERROR(SUM(J7,K7,M7),0) -> 1250 | O7: =IFERROR(SUM(L7),0) -> 0 | P7: Illustrative estimate (USD). Internal cost = staff days x 250/day blended rate. External and tool costs are indicative list pricing, not quotations.
A8: 0.16 | B8: 🏛️ GV Govern | C8: Security Organisational Structure | D8: =IFERROR(IF('GV Govern'!P7="⏳ Complete rating and target to generate recommendation.","⏳ Rate this control in the domain sheet to auto-generate.",'GV Govern'!P7),"—") -> Standardise Security Organisational Structure: formalise all documentation, apply the control consistently across all in-scope assets, close remaining coverage gaps, and ensure evidence is collected routinely. Exceptions must be formally managed with named owners and defined expiry dates. | E8: High (1-3 months) | F8: Q2 2027 | G8: Marc Etonde — Head of IT | H8: Not Started | J8: 3000 | N8: =IFERROR(SUM(J8,K8,M8),0) -> 3000 | O8: =IFERROR(SUM(L8),0) -> 0 | P8: Illustrative estimate (USD). Internal cost = staff days x 250/day blended rate. External and tool costs are indicative list pricing, not quotations.
A9: 0.32 | B9: 🏛️ GV Govern | C9: Board-Level Cybersecurity Oversight | D9: =IFERROR(IF('GV Govern'!P8="⏳ Complete rating and target to generate recommendation.","⏳ Rate this control in the domain sheet to auto-generate.",'GV Govern'!P8),"—") -> Standardise Board-Level Cybersecurity Oversight: formalise all documentation, apply the control consistently across all in-scope assets, close remaining coverage gaps, and ensure evidence is collected routinely. Exceptions must be formally managed with named owners and defined expiry dates. | E9: High (1-3 months) | F9: Q2 2027 | G9: Jean-Paul Nkeng — Managing Director | H9: Not Started | J9: 3000 | N9: =IFERROR(SUM(J9,K9,M9),0) -> 3000 | O9: =IFERROR(SUM(L9),0) -> 0 | P9: Illustrative estimate (USD). Internal cost = staff days x 250/day blended rate. External and tool costs are indicative list pricing, not quotations.
A10: 0.16 | B10: 🏛️ GV Govern | C10: Security Policy Framework & Hierarchy | D10: =IFERROR(IF('GV Govern'!P9="⏳ Complete rating and target to generate recommendation.","⏳ Rate this control in the domain sheet to auto-generate.",'GV Govern'!P9),"—") -> Standardise Security Policy Framework & Hierarchy: formalise all documentation, apply the control consistently across all in-scope assets, close remaining coverage gaps, and ensure evidence is collected routinely. Exceptions must be formally managed with named owners and defined expiry dates. | E10: Medium (1-4 weeks) | F10: Q3 2027 | G10: Marie Fotso — Legal & Compliance Counsel | H10: Not Started | J10: 1250 | N10: =IFERROR(SUM(J10,K10,M10),0) -> 1250 | O10: =IFERROR(SUM(L10),0) -> 0 | P10: Illustrative estimate (USD). Internal cost = staff days x 250/day blended rate. External and tool costs are indicative list pricing, not quotations.
A11: 0.16 | B11: 🏛️ GV Govern | C11: Policy Attestation & Enforcement | D11: =IFERROR(IF('GV Govern'!P10="⏳ Complete rating and target to generate recommendation.","⏳ Rate this control in the domain sheet to auto-generate.",'GV Govern'!P10),"—") -> Standardise Policy Attestation & Enforcement: formalise all documentation, apply the control consistently across all in-scope assets, close remaining coverage gaps, and ensure evidence is collected routinely. Exceptions must be formally managed with named owners and defined expiry dates. | E11: Medium (1-4 weeks) | F11: Q3 2027 | G11: Ruth Anong — HR Manager | H11: Not Started | J11: 1250 | N11: =IFERROR(SUM(J11,K11,M11),0) -> 1250 | O11: =IFERROR(SUM(L11),0) -> 0 | P11: Illustrative estimate (USD). Internal cost = staff days x 250/day blended rate. External and tool costs are indicative list pricing, not quotations.
A12: 0.32 | B12: 🏛️ GV Govern | C12: Policy Exception Governance | D12: =IFERROR(IF('GV Govern'!P11="⏳ Complete rating and target to generate recommendation.","⏳ Rate this control in the domain sheet to auto-generate.",'GV Govern'!P11),"—") -> Standardise Policy Exception Governance: formalise all documentation, apply the control consistently across all in-scope assets, close remaining coverage gaps, and ensure evidence is collected routinely. Exceptions must be formally managed with named owners and defined expiry dates. | E12: High (1-3 months) | F12: Q2 2027 | G12: Marc Etonde — Head of IT | H12: Not Started | J12: 3000 | N12: =IFERROR(SUM(J12,K12,M12),0) -> 3000 | O12: =IFERROR(SUM(L12),0) -> 0 | P12: Illustrative estimate (USD). Internal cost = staff days x 250/day blended rate. External and tool costs are indicative list pricing, not quotations.
A13: 0.32 | B13: 🏛️ GV Govern | C13: Control Standards Management | D13: =IFERROR(IF('GV Govern'!P12="⏳ Complete rating and target to generate recommendation.","⏳ Rate this control in the domain sheet to auto-generate.",'GV Govern'!P12),"—") -> Standardise Control Standards Management: formalise all documentation, apply the control consistently across all in-scope assets, close remaining coverage gaps, and ensure evidence is collected routinely. Exceptions must be formally managed with named owners and defined expiry dates. | E13: High (1-3 months) | F13: Q2 2027 | G13: Marc Etonde — Head of IT | H13: Not Started | J13: 3000 | N13: =IFERROR(SUM(J13,K13,M13),0) -> 3000 | O13: =IFERROR(SUM(L13),0) -> 0 | P13: Illustrative estimate (USD). Internal cost = staff days x 250/day blended rate. External and tool costs are indicative list pricing, not quotations.
A14: 0.32 | B14: 🏛️ GV Govern | C14: Regulatory Obligation Register & Mapping | D14: =IFERROR(IF('GV Govern'!P13="⏳ Complete rating and target to generate recommendation.","⏳ Rate this control in the domain sheet to auto-generate.",'GV Govern'!P13),"—") -> Instrument Regulatory Obligation Register & Mapping with measurable KPIs: define performance thresholds (coverage %, SLA adherence, exception count), establish automated telemetry where possible, and integrate reporting into quarterly governance cycles. Evidence must be system-generated and reviewed at each governance cycle. | E14: High (1-3 months) | F14: Q1 2027 | G14: Marie Fotso — Legal & Compliance Counsel | H14: Not Started | J14: 3000 | N14: =IFERROR(SUM(J14,K14,M14),0) -> 3000 | O14: =IFERROR(SUM(L14),0) -> 0 | P14: Illustrative estimate (USD). Internal cost = staff days x 250/day blended rate. External and tool costs are indicative list pricing, not quotations.
A15: 0.48 | B15: 🏛️ GV Govern | C15: Regulatory Change Management | D15: =IFERROR(IF('GV Govern'!P14="⏳ Complete rating and target to generate recommendation.","⏳ Rate this control in the domain sheet to auto-generate.",'GV Govern'!P14),"—") -> Instrument Regulatory Change Management with measurable KPIs: define performance thresholds (coverage %, SLA adherence, exception count), establish automated telemetry where possible, and integrate reporting into quarterly governance cycles. Evidence must be system-generated and reviewed at each governance cycle. | E15: High (1-3 months) | F15: Q1 2027 | G15: Marie Fotso — Legal & Compliance Counsel | H15: Not Started | J15: 3000 | N15: =IFERROR(SUM(J15,K15,M15),0) -> 3000 | O15: =IFERROR(SUM(L15),0) -> 0 | P15: Illustrative estimate (USD). Internal cost = staff days x 250/day blended rate. External and tool costs are indicative list pricing, not quotations.
A16: 0.48 | B16: 🏛️ GV Govern | C16: Security Standards for Third Parties | D16: =IFERROR(IF('GV Govern'!P15="⏳ Complete rating and target to generate recommendation.","⏳ Rate this control in the domain sheet to auto-generate.",'GV Govern'!P15),"—") -> Instrument Security Standards for Third Parties with measurable KPIs: define performance thresholds (coverage %, SLA adherence, exception count), establish automated telemetry where possible, and integrate reporting into quarterly governance cycles. Evidence must be system-generated and reviewed at each governance cycle. | E16: High (1-3 months) | F16: Q1 2027 | G16: Linda Ojo — Procurement Officer | H16: Not Started | J16: 3000 | N16: =IFERROR(SUM(J16,K16,M16),0) -> 3000 | O16: =IFERROR(SUM(L16),0) -> 0 | P16: Illustrative estimate (USD). Internal cost = staff days x 250/day blended rate. External and tool costs are indicative list pricing, not quotations.
A17: 0.16 | B17: 🏛️ GV Govern | C17: Enterprise Risk Framework Integration | D17: =IFERROR(IF('GV Govern'!P16="⏳ Complete rating and target to generate recommendation.","⏳ Rate this control in the domain sheet to auto-generate.",'GV Govern'!P16),"—") -> Standardise Enterprise Risk Framework Integration: formalise all documentation, apply the control consistently across all in-scope assets, close remaining coverage gaps, and ensure evidence is collected routinely. Exceptions must be formally managed with named owners and defined expiry dates. | E17: High (1-3 months) | F17: Q2 2027 | G17: Marc Etonde — Head of IT | H17: Not Started | J17: 3000 | N17: =IFERROR(SUM(J17,K17,M17),0) -> 3000 | O17: =IFERROR(SUM(L17),0) -> 0 | P17: Illustrative estimate (USD). Internal cost = staff days x 250/day blended rate. External and tool costs are indicative list pricing, not quotations.
... A24: 0.48 | B24: 🏛️ GV Govern | C24: Fourth-Party & Sub-Processor Mapping | D24: =IFERROR(IF('GV Govern'!P23="⏳ Complete rating and target to generate recommendation.","⏳ Rate this control in the domain sheet to auto-generate.",'GV Govern'!P23),"—") -> Instrument Fourth-Party & Sub-Processor Mapping with measurable KPIs: define performance thresholds (coverage %, SLA adherence, exception count), establish automated telemetry where possible, and integrate reporting into quarterly governance cycles. Evidence must be system-generated and reviewed at each governance cycle. | E24: High (1-3 months) | F24: Q1 2027 | G24: Linda Ojo — Procurement Officer | H24: Not Started | J24: 3000 | N24: =IFERROR(SUM(J24,K24,M24),0) -> 3000 | O24: =IFERROR(SUM(L24),0) -> 0 | P24: Illustrative estimate (USD). Internal cost = staff days x 250/day blended rate. External and tool costs are indicative list pricing, not quotations.
A25: 0 | B25: 🏛️ GV Govern | C25: DORA TPSP Critical Register | D25: =IFERROR(IF('GV Govern'!P24="⏳ Complete rating and target to generate recommendation.","⏳ Rate this control in the domain sheet to auto-generate.",'GV Govern'!P24),"—") -> ⏳ Rate this control in the domain sheet to auto-generate. | G25: Linda Ojo — Procurement Officer | H25: Deferred | N25: =IFERROR(SUM(J25,K25,M25),0) -> 0 | O25: =IFERROR(SUM(L25),0) -> 0 | P25: Out of scope for this organisation — no cost carried.
A26: 0.16 | B26: 🏛️ GV Govern | C26: Software Supply Chain Security Governance | D26: =IFERROR(IF('GV Govern'!P25="⏳ Complete rating and target to generate recommendation.","⏳ Rate this control in the domain sheet to auto-generate.",'GV Govern'!P25),"—") -> Standardise Software Supply Chain Security Governance: formalise all documentation, apply the control consistently across all in-scope assets, close remaining coverage gaps, and ensure evidence is collected routinely. Exceptions must be formally managed with named owners and defined expiry dates. | E26: High (1-3 months) | F26: Q2 2027 | G26: Tunde Balogun — Lead Software Engineer | H26: Not Started | J26: 3000 | N26: =IFERROR(SUM(J26,K26,M26),0) -> 3000 | O26: =IFERROR(SUM(L26),0) -> 0 | P26: Illustrative estimate (USD). Internal cost = staff days x 250/day blended rate. External and tool costs are indicative list pricing, not quotations.
A27: 0.32 | B27: 🏛️ GV Govern | C27: Supplier Resilience Requirements | D27: =IFERROR(IF('GV Govern'!P26="⏳ Complete rating and target to generate recommendation.","⏳ Rate this control in the domain sheet to auto-generate.",'GV Govern'!P26),"—") -> Standardise Supplier Resilience Requirements: formalise all documentation, apply the control consistently across all in-scope assets, close remaining coverage gaps, and ensure evidence is collected routinely. Exceptions must be formally managed with named owners and defined expiry dates. | E27: High (1-3 months) | F27: Q2 2027 | G27: Linda Ojo — Procurement Officer | H27: Not Started | J27: 3000 | N27: =IFERROR(SUM(J27,K27,M27),0) -> 3000 | O27: =IFERROR(SUM(L27),0) -> 0 | P27: Illustrative estimate (USD). Internal cost = staff days x 250/day blended rate. External and tool costs are indicative list pricing, not quotations.
A28: 0.48 | B28: 🏛️ GV Govern | C28: Privacy Governance & DPO/Privacy Lead | D28: =IFERROR(IF('GV Govern'!P27="⏳ Complete rating and target to generate recommendation.","⏳ Rate this control in the domain sheet to auto-generate.",'GV Govern'!P27),"—") -> Instrument Privacy Governance & DPO/Privacy Lead with measurable KPIs: define performance thresholds (coverage %, SLA adherence, exception count), establish automated telemetry where possible, and integrate reporting into quarterly governance cycles. Evidence must be system-generated and reviewed at each governance cycle. | E28: High (1-3 months) | F28: Q2 2027 | G28: Marie Fotso — Legal & Compliance Counsel | H28: Not Started | J28: 3000 | K28: 0 | L28: 0 | M28: 0 | N28: =IFERROR(SUM(J28,K28,M28),0) -> 3000 | O28: =IFERROR(SUM(L28),0) -> 0 | P28: Illustrative estimate (USD). Internal cost = staff days x 250/day blended rate. External and tool costs are indicative list pricing, not quotations.
A29: 0.32 | B29: 🏛️ GV Govern | C29: Records of Processing Activities (ROPA) | D29: =IFERROR(IF('GV Govern'!P28="⏳ Complete rating and target to generate recommendation.","⏳ Rate this control in the domain sheet to auto-generate.",'GV Govern'!P28),"—") -> Instrument Records of Processing Activities (ROPA) with measurable KPIs: define performance thresholds (coverage %, SLA adherence, exception count), establish automated telemetry where possible, and integrate reporting into quarterly governance cycles. Evidence must be system-generated and reviewed at each governance cycle. | E29: High (1-3 months) | F29: Q1 2027 | G29: Marie Fotso — Legal & Compliance Counsel | H29: Not Started | J29: 3000 | N29: =IFERROR(SUM(J29,K29,M29),0) -> 3000 | O29: =IFERROR(SUM(L29),0) -> 0 | P29: Illustrative estimate (USD). Internal cost = staff days x 250/day blended rate. External and tool costs are indicative list pricing, not quotations.
A30: 0.48 | B30: 🏛️ GV Govern | C30: Data Protection Impact Assessments (DPIAs) | D30: =IFERROR(IF('GV Govern'!P29="⏳ Complete rating and target to generate recommendation.","⏳ Rate this control in the domain sheet to auto-generate.",'GV Govern'!P29),"—") -> Instrument Data Protection Impact Assessments (DPIAs) with measurable KPIs: define performance thresholds (coverage %, SLA adherence, exception count), establish automated telemetry where possible, and integrate reporting into quarterly governance cycles. Evidence must be system-generated and reviewed at each governance cycle. | E30: High (1-3 months) | F30: Q1 2027 | G30: Marie Fotso — Legal & Compliance Counsel | H30: Not Started | J30: 3000 | N30: =IFERROR(SUM(J30,K30,M30),0) -> 3000 | O30: =IFERROR(SUM(L30),0) -> 0 | P30: Illustrative estimate (USD). Internal cost = staff days x 250/day blended rate. External and tool costs are indicative list pricing, not quotations.
A31: 0.48 | B31: 🏛️ GV Govern | C31: Cross-Border Data Transfer Controls | D31: =IFERROR(IF('GV Govern'!P30="⏳ Complete rating and target to generate recommendation.","⏳ Rate this control in the domain sheet to auto-generate.",'GV Govern'!P30),"—") -> Instrument Cross-Border Data Transfer Controls with measurable KPIs: define performance thresholds (coverage %, SLA adherence, exception count), establish automated telemetry where possible, and integrate reporting into quarterly governance cycles. Evidence must be system-generated and reviewed at each governance cycle. | E31: High (1-3 months) | F31: Q1 2027 | G31: Marie Fotso — Legal & Compliance Counsel | H31: Not Started | J31: 3000 | N31: =IFERROR(SUM(J31,K31,M31),0) -> 3000 | O31: =IFERROR(SUM(L31),0) -> 0 | P31: Illustrative estimate (USD). Internal cost = staff days x 250/day blended rate. External and tool costs are indicative list pricing, not quotations.
A32: 0.16 | B32: 🏛️ GV Govern | C32: Internal & External Audit Programme | D32: =IFERROR(IF('GV Govern'!P31="⏳ Complete rating and target to generate recommendation.","⏳ Rate this control in the domain sheet to auto-generate.",'GV Govern'!P31),"—") -> Standardise Internal & External Audit Programme: formalise all documentation, apply the control consistently across all in-scope assets, close remaining coverage gaps, and ensure evidence is collected routinely. Exceptions must be formally managed with named owners and defined expiry dates. | E32: High (1-3 months) | F32: Q2 2027 | G32: Jean-Paul Nkeng — Managing Director | H32: Not Started | J32: 3000 | K32: 45000 | L32: 0 | M32: 0 | N32: =IFERROR(SUM(J32,K32,M32),0) -> 48000 | O32: =IFERROR(SUM(L32),0) -> 0 | P32: Illustrative estimate (USD). Internal cost = staff days x 250/day blended rate. External and tool costs are indicative list pricing, not quotations.
A33: 0.1 | B33: 🔍 ID Identify | C33: IT Hardware Asset Inventory (CMDB) | D33: =IFERROR(IF('ID Identify'!P4="⏳ Complete rating and target to generate recommendation.","⏳ Rate this control in the domain sheet to auto-generate.",'ID Identify'!P4),"—") -> Standardise IT Hardware Asset Inventory (CMDB): formalise all documentation, apply the control consistently across all in-scope assets, close remaining coverage gaps, and ensure evidence is collected routinely. Exceptions must be formally managed with named owners and defined expiry dates. | E33: Medium (1-4 weeks) | F33: Q3 2027 | G33: Grace Ayuk — IT Operations Manager | H33: Not Started | J33: 1250 | N33: =IFERROR(SUM(J33,K33,M33),0) -> 1250 | O33: =IFERROR(SUM(L33),0) -> 0 | P33: Illustrative estimate (USD). Internal cost = staff days x 250/day blended rate. External and tool costs are indicative list pricing, not quotations.
A34: 0.1 | B34: 🔍 ID Identify | C34: Software Asset Inventory | D34: =IFERROR(IF('ID Identify'!P5="⏳ Complete rating and target to generate recommendation.","⏳ Rate this control in the domain sheet to auto-generate.",'ID Identify'!P5),"—") -> Standardise Software Asset Inventory: formalise all documentation, apply the control consistently across all in-scope assets, close remaining coverage gaps, and ensure evidence is collected routinely. Exceptions must be formally managed with named owners and defined expiry dates. | E34: High (1-3 months) | F34: Q3 2027 | G34: Grace Ayuk — IT Operations Manager | H34: Not Started | J34: 3000 | N34: =IFERROR(SUM(J34,K34,M34),0) -> 3000 | O34: =IFERROR(SUM(L34),0) -> 0 | P34: Illustrative estimate (USD). Internal cost = staff days x 250/day blended rate. External and tool costs are indicative list pricing, not quotations.
A35: 0.1 | B35: 🔍 ID Identify | C35: Cloud Infrastructure Asset Inventory | D35: =IFERROR(IF('ID Identify'!P6="⏳ Complete rating and target to generate recommendation.","⏳ Rate this control in the domain sheet to auto-generate.",'ID Identify'!P6),"—") -> Standardise Cloud Infrastructure Asset Inventory: formalise all documentation, apply the control consistently across all in-scope assets, close remaining coverage gaps, and ensure evidence is collected routinely. Exceptions must be formally managed with named owners and defined expiry dates. | E35: Medium (1-4 weeks) | F35: Q3 2027 | G35: Sam Ncube — DevOps Engineer | H35: Not Started | J35: 1250 | N35: =IFERROR(SUM(J35,K35,M35),0) -> 1250 | O35: =IFERROR(SUM(L35),0) -> 0 | P35: Illustrative estimate (USD). Internal cost = staff days x 250/day blended rate. External and tool costs are indicative list pricing, not quotations.
A36: 0.2 | B36: 🔍 ID Identify | C36: SaaS & Shadow IT Discovery | D36: =IFERROR(IF('ID Identify'!P7="⏳ Complete rating and target to generate recommendation.","⏳ Rate this control in the domain sheet to auto-generate.",'ID Identify'!P7),"—") -> Instrument SaaS & Shadow IT Discovery with measurable KPIs: define performance thresholds (coverage %, SLA adherence, exception count), establish automated telemetry where possible, and integrate reporting into quarterly governance cycles. Evidence must be system-generated and reviewed at each governance cycle. | E36: High (1-3 months) | F36: Q2 2027 | G36: Marc Etonde — Head of IT | H36: Not Started | J36: 3000 | N36: =IFERROR(SUM(J36,K36,M36),0) -> 3000 | O36: =IFERROR(SUM(L36),0) -> 0 | P36: Illustrative estimate (USD). Internal cost = staff days x 250/day blended rate. External and tool costs are indicative list pricing, not quotations.
A37: 0 | B37: 🔍 ID Identify | C37: Software Bill of Materials (SBOM) | D37: =IFERROR(IF('ID Identify'!P8="⏳ Complete rating and target to generate recommendation.","⏳ Rate this control in the domain sheet to auto-generate.",'ID Identify'!P8),"—") -> Standardise Software Bill of Materials (SBOM): formalise all documentation, apply the control consistently across all in-scope assets, close remaining coverage gaps, and ensure evidence is collected routinely. Exceptions must be formally managed with named owners and defined expiry dates. | E37: High (1-3 months) | F37: Q3 2027 | G37: Tunde Balogun — Lead Software Engineer | H37: Not Started | J37: 3000 | N37: =IFERROR(SUM(J37,K37,M37),0) -> 3000 | O37: =IFERROR(SUM(L37),0) -> 0 | P37: Illustrative estimate (USD). Internal cost = staff days x 250/day blended rate. External and tool costs are indicative list pricing, not quotations.
A38: 0.3 | B38: 🔍 ID Identify | C38: Network Topology & Architecture Documentation | D38: =IFERROR(IF('ID Identify'!P9="⏳ Complete rating and target to generate recommendation.","⏳ Rate this control in the domain sheet to auto-generate.",'ID Identify'!P9),"—") -> Instrument Network Topology & Architecture Documentation with measurable KPIs: define performance thresholds (coverage %, SLA adherence, exception count), establish automated telemetry where possible, and integrate reporting into quarterly governance cycles. Evidence must be system-generated and reviewed at each governance cycle. | E38: High (1-3 months) | F38: Q3 2027 | G38: Marc Etonde — Head of IT | H38: Not Started | J38: 3000 | N38: =IFERROR(SUM(J38,K38,M38),0) -> 3000 | O38: =IFERROR(SUM(L38),0) -> 0 | P38: Illustrative estimate (USD). Internal cost = staff days x 250/day blended rate. External and tool costs are indicative list pricing, not quotations.
A39: 0.1 | B39: 🔍 ID Identify | C39: Technology Lifecycle Management | D39: =IFERROR(IF('ID Identify'!P10="⏳ Complete rating and target to generate recommendation.","⏳ Rate this control in the domain sheet to auto-generate.",'ID Identify'!P10),"—") -> Standardise Technology Lifecycle Management: formalise all documentation, apply the control consistently across all in-scope assets, close remaining coverage gaps, and ensure evidence is collected routinely. Exceptions must be formally managed with named owners and defined expiry dates. | E39: High (1-3 months) | F39: Q3 2027 | G39: Grace Ayuk — IT Operations Manager | H39: Not Started | J39: 3000 | N39: =IFERROR(SUM(J39,K39,M39),0) -> 3000 | O39: =IFERROR(SUM(L39),0) -> 0 | P39: Illustrative estimate (USD). Internal cost = staff days x 250/day blended rate. External and tool costs are indicative list pricing, not quotations.
A40: 0.3 | B40: 🔍 ID Identify | C40: Data Classification Framework & Implementation | D40: =IFERROR(IF('ID Identify'!P11="⏳ Complete rating and target to generate recommendation.","⏳ Rate this control in the domain sheet to auto-generate.",'ID Identify'!P11),"—") -> Instrument Data Classification Framework & Implementation with measurable KPIs: define performance thresholds (coverage %, SLA adherence, exception count), establish automated telemetry where possible, and integrate reporting into quarterly governance cycles. Evidence must be system-generated and reviewed at each governance cycle. | E40: High (1-3 months) | F40: Q2 2027 | G40: Marie Fotso — Legal & Compliance Counsel | H40: Not Started | J40: 3000 | N40: =IFERROR(SUM(J40,K40,M40),0) -> 3000 | O40: =IFERROR(SUM(L40),0) -> 0 | P40: Illustrative estimate (USD). Internal cost = staff days x 250/day blended rate. External and tool costs are indicative list pricing, not quotations.
